[2023-05-29T10:19:55.270+0000] {taskinstance.py:1103} INFO - Dependencies all met for dep_context=non-requeueable deps ti=<TaskInstance: user_processing.is_api_available manual__2023-05-29T10:19:52.843245+00:00 [queued]>
[2023-05-29T10:19:55.275+0000] {taskinstance.py:1103} INFO - Dependencies all met for dep_context=requeueable deps ti=<TaskInstance: user_processing.is_api_available manual__2023-05-29T10:19:52.843245+00:00 [queued]>
[2023-05-29T10:19:55.276+0000] {taskinstance.py:1308} INFO - Starting attempt 1 of 1
[2023-05-29T10:19:55.284+0000] {taskinstance.py:1327} INFO - Executing <Task(HttpSensor): is_api_available> on 2023-05-29 10:19:52.843245+00:00
[2023-05-29T10:19:55.288+0000] {standard_task_runner.py:57} INFO - Started process 676 to run task
[2023-05-29T10:19:55.292+0000] {standard_task_runner.py:84} INFO - Running: ['***', 'tasks', 'run', 'user_processing', 'is_api_available', 'manual__2023-05-29T10:19:52.843245+00:00', '--job-id', '8', '--raw', '--subdir', 'DAGS_FOLDER/user_processing.py', '--cfg-path', '/tmp/tmpe0xc86ia']
[2023-05-29T10:19:55.294+0000] {standard_task_runner.py:85} INFO - Job 8: Subtask is_api_available
[2023-05-29T10:19:55.334+0000] {task_command.py:410} INFO - Running <TaskInstance: user_processing.is_api_available manual__2023-05-29T10:19:52.843245+00:00 [running]> on host 280eb86c6caa
[2023-05-29T10:19:55.388+0000] {taskinstance.py:1547} INFO - Exporting env vars: AIRFLOW_CTX_DAG_OWNER='***' AIRFLOW_CTX_DAG_ID='user_processing' AIRFLOW_CTX_TASK_ID='is_api_available' AIRFLOW_CTX_EXECUTION_DATE='2023-05-29T10:19:52.843245+00:00' AIRFLOW_CTX_TRY_NUMBER='1' AIRFLOW_CTX_DAG_RUN_ID='manual__2023-05-29T10:19:52.843245+00:00'
[2023-05-29T10:19:55.389+0000] {http.py:122} INFO - Poking: api/
[2023-05-29T10:19:55.404+0000] {taskinstance.py:1824} ERROR - Task failed with exception
Traceback (most recent call last):
  File "/home/airflow/.local/lib/python3.7/site-packages/airflow/sensors/base.py", line 225, in execute
    raise e
  File "/home/airflow/.local/lib/python3.7/site-packages/airflow/sensors/base.py", line 212, in execute
    poke_return = self.poke(context)
  File "/home/airflow/.local/lib/python3.7/site-packages/airflow/providers/http/sensors/http.py", line 137, in poke
    raise exc
  File "/home/airflow/.local/lib/python3.7/site-packages/airflow/providers/http/sensors/http.py", line 128, in poke
    extra_options=self.extra_options,
  File "/home/airflow/.local/lib/python3.7/site-packages/airflow/providers/http/hooks/http.py", line 148, in run
    session = self.get_conn(headers)
  File "/home/airflow/.local/lib/python3.7/site-packages/airflow/providers/http/hooks/http.py", line 100, in get_conn
    conn = self.get_connection(self.http_conn_id)
  File "/home/airflow/.local/lib/python3.7/site-packages/airflow/hooks/base.py", line 72, in get_connection
    conn = Connection.get_connection_from_secrets(conn_id)
  File "/home/airflow/.local/lib/python3.7/site-packages/airflow/models/connection.py", line 434, in get_connection_from_secrets
    raise AirflowNotFoundException(f"The conn_id `{conn_id}` isn't defined")
airflow.exceptions.AirflowNotFoundException: The conn_id `user_api` isn't defined
[2023-05-29T10:19:55.407+0000] {taskinstance.py:1350} INFO - Marking task as FAILED. dag_id=user_processing, task_id=is_api_available, execution_date=20230529T101952, start_date=20230529T101955, end_date=20230529T101955
[2023-05-29T10:19:55.413+0000] {standard_task_runner.py:109} ERROR - Failed to execute job 8 for task is_api_available (The conn_id `user_api` isn't defined; 676)
[2023-05-29T10:19:55.423+0000] {local_task_job_runner.py:225} INFO - Task exited with return code 1
[2023-05-29T10:19:55.446+0000] {taskinstance.py:2651} INFO - 0 downstream tasks scheduled from follow-on schedule check
